[2023-08-30 05:55:36 +0000] [47998] [INFO] Starting gunicorn 21.2.0
[2023-08-30 05:55:36 +0000] [47998] [INFO] Listening at: unix:/webcomic-backend.sock (47998)
[2023-08-30 05:55:36 +0000] [47998] [INFO] Using worker: sync
[2023-08-30 05:55:36 +0000] [47999] [INFO] Booting worker with pid: 47999
[2023-08-30 05:55:36 +0000] [48000] [INFO] Booting worker with pid: 48000
[2023-08-30 05:56:52 +0000] [47999] [INFO] Worker exiting (pid: 47999)
[2023-08-30 05:56:52 +0000] [48000] [INFO] Worker exiting (pid: 48000)
[2023-08-30 05:56:52 +0000] [47998] [INFO] Handling signal: term
[2023-08-30 05:56:52 +0000] [47998] [ERROR] Worker (pid:47999) was sent SIGTERM!
[2023-08-30 05:56:52 +0000] [47998] [INFO] Shutting down: Master
[2023-08-30 05:56:53 +0000] [48209] [INFO] Starting gunicorn 21.2.0
[2023-08-30 05:56:53 +0000] [48209] [INFO] Listening at: unix:/webcomic-backend.sock (48209)
[2023-08-30 05:56:53 +0000] [48209] [INFO] Using worker: sync
[2023-08-30 05:56:53 +0000] [48213] [INFO] Booting worker with pid: 48213
[2023-08-30 05:56:53 +0000] [48214] [INFO] Booting worker with pid: 48214
[2023-08-30 05:57:20 +0000] [48214] [INFO] Worker exiting (pid: 48214)
[2023-08-30 05:57:20 +0000] [48213] [INFO] Worker exiting (pid: 48213)
[2023-08-30 05:57:20 +0000] [48209] [INFO] Handling signal: term
[2023-08-30 05:57:20 +0000] [48209] [ERROR] Worker (pid:48214) was sent SIGTERM!
[2023-08-30 05:57:20 +0000] [48209] [ERROR] Worker (pid:48213) was sent SIGTERM!
[2023-08-30 05:57:20 +0000] [48209] [INFO] Shutting down: Master
[2023-08-30 05:57:21 +0000] [48265] [INFO] Starting gunicorn 21.2.0
[2023-08-30 05:57:21 +0000] [48265] [INFO] Listening at: unix:/webcomic-backend.sock (48265)
[2023-08-30 05:57:21 +0000] [48265] [INFO] Using worker: sync
[2023-08-30 05:57:21 +0000] [48269] [INFO] Booting worker with pid: 48269
[2023-08-30 05:57:21 +0000] [48270] [INFO] Booting worker with pid: 48270
[2023-08-30 06:12:48 +0000] [48270] [INFO] Worker exiting (pid: 48270)
[2023-08-30 06:12:48 +0000] [48269] [INFO] Worker exiting (pid: 48269)
[2023-08-30 06:12:48 +0000] [48265] [ERROR] Worker (pid:48270) was sent SIGTERM!
[2023-08-30 06:12:48 +0000] [48265] [INFO] Handling signal: term
[2023-08-30 06:12:48 +0000] [48265] [ERROR] Worker (pid:48269) was sent SIGTERM!
[2023-08-30 06:12:48 +0000] [48265] [INFO] Shutting down: Master
[2023-08-30 06:12:49 +0000] [49520] [INFO] Starting gunicorn 21.2.0
[2023-08-30 06:12:49 +0000] [49520] [INFO] Listening at: http://127.0.0.1:6900 (49520)
[2023-08-30 06:12:49 +0000] [49520] [INFO] Using worker: sync
[2023-08-30 06:12:49 +0000] [49522] [INFO] Booting worker with pid: 49522
[2023-08-30 06:12:49 +0000] [49524] [INFO] Booting worker with pid: 49524
[2023-11-08 01:53:28 +0000] [14550] [INFO] Starting gunicorn 21.2.0
[2023-11-08 01:53:28 +0000] [14550] [INFO] Listening at: http://127.0.0.1:6900 (14550)
[2023-11-08 01:53:28 +0000] [14550] [INFO] Using worker: sync
[2023-11-08 01:53:28 +0000] [14551] [INFO] Booting worker with pid: 14551
[2023-11-08 01:53:28 +0000] [14552] [INFO] Booting worker with pid: 14552
[2023-11-08 01:53:29 +0000] [14551] [ERROR] Exception in worker process
Traceback (most recent call last):
  File "/home/bitnami/webcomic-backend/venv/lib/python3.9/site-packages/gunicorn/arbiter.py", line 609, in spawn_worker
    worker.init_process()
  File "/home/bitnami/webcomic-backend/venv/lib/python3.9/site-packages/gunicorn/workers/base.py", line 134, in init_process
    self.load_wsgi()
  File "/home/bitnami/webcomic-backend/venv/lib/python3.9/site-packages/gunicorn/workers/base.py", line 146, in load_wsgi
    self.wsgi = self.app.wsgi()
  File "/home/bitnami/webcomic-backend/venv/lib/python3.9/site-packages/gunicorn/app/base.py", line 67, in wsgi
    self.callable = self.load()
  File "/home/bitnami/webcomic-backend/venv/lib/python3.9/site-packages/gunicorn/app/wsgiapp.py", line 58, in load
    return self.load_wsgiapp()
  File "/home/bitnami/webcomic-backend/venv/lib/python3.9/site-packages/gunicorn/app/wsgiapp.py", line 48, in load_wsgiapp
    return util.import_app(self.app_uri)
  File "/home/bitnami/webcomic-backend/venv/lib/python3.9/site-packages/gunicorn/util.py", line 371, in import_app
    mod = importlib.import_module(module)
  File "/usr/lib/python3.9/importlib/__init__.py", line 127, in import_module
    return _bootstrap._gcd_import(name[level:], package, level)
  File "<frozen importlib._bootstrap>", line 1030, in _gcd_import
  File "<frozen importlib._bootstrap>", line 1007, in _find_and_load
  File "<frozen importlib._bootstrap>", line 986, in _find_and_load_unlocked
  File "<frozen importlib._bootstrap>", line 680, in _load_unlocked
  File "<frozen importlib._bootstrap_external>", line 790, in exec_module
  File "<frozen importlib._bootstrap>", line 228, in _call_with_frames_removed
  File "/home/bitnami/webcomic-backend/src/wsgi.py", line 5, in <module>
    from service.Services import ChapterService
  File "/home/bitnami/webcomic-backend/src/service/Services.py", line 5, in <module>
    from service.caches import ChapterCache
  File "/home/bitnami/webcomic-backend/src/service/caches.py", line 9, in <module>
    class ChapterCache:
  File "/home/bitnami/webcomic-backend/src/service/caches.py", line 82, in ChapterCache
    def get_chapter_by_number(self, chapter_num) -> ComicChapterExtended | None:
TypeError: unsupported operand type(s) for |: 'type' and 'NoneType'
[2023-11-08 01:53:29 +0000] [14552] [ERROR] Exception in worker process
Traceback (most recent call last):
  File "/home/bitnami/webcomic-backend/venv/lib/python3.9/site-packages/gunicorn/arbiter.py", line 609, in spawn_worker
    worker.init_process()
  File "/home/bitnami/webcomic-backend/venv/lib/python3.9/site-packages/gunicorn/workers/base.py", line 134, in init_process
    self.load_wsgi()
  File "/home/bitnami/webcomic-backend/venv/lib/python3.9/site-packages/gunicorn/workers/base.py", line 146, in load_wsgi
    self.wsgi = self.app.wsgi()
  File "/home/bitnami/webcomic-backend/venv/lib/python3.9/site-packages/gunicorn/app/base.py", line 67, in wsgi
    self.callable = self.load()
  File "/home/bitnami/webcomic-backend/venv/lib/python3.9/site-packages/gunicorn/app/wsgiapp.py", line 58, in load
    return self.load_wsgiapp()
  File "/home/bitnami/webcomic-backend/venv/lib/python3.9/site-packages/gunicorn/app/wsgiapp.py", line 48, in load_wsgiapp
    return util.import_app(self.app_uri)
  File "/home/bitnami/webcomic-backend/venv/lib/python3.9/site-packages/gunicorn/util.py", line 371, in import_app
    mod = importlib.import_module(module)
  File "/usr/lib/python3.9/importlib/__init__.py", line 127, in import_module
    return _bootstrap._gcd_import(name[level:], package, level)
  File "<frozen importlib._bootstrap>", line 1030, in _gcd_import
  File "<frozen importlib._bootstrap>", line 1007, in _find_and_load
  File "<frozen importlib._bootstrap>", line 986, in _find_and_load_unlocked
  File "<frozen importlib._bootstrap>", line 680, in _load_unlocked
  File "<frozen importlib._bootstrap_external>", line 790, in exec_module
  File "<frozen importlib._bootstrap>", line 228, in _call_with_frames_removed
  File "/home/bitnami/webcomic-backend/src/wsgi.py", line 5, in <module>
    from service.Services import ChapterService
  File "/home/bitnami/webcomic-backend/src/service/Services.py", line 5, in <module>
    from service.caches import ChapterCache
  File "/home/bitnami/webcomic-backend/src/service/caches.py", line 9, in <module>
    class ChapterCache:
  File "/home/bitnami/webcomic-backend/src/service/caches.py", line 82, in ChapterCache
    def get_chapter_by_number(self, chapter_num) -> ComicChapterExtended | None:
TypeError: unsupported operand type(s) for |: 'type' and 'NoneType'
[2023-11-08 01:53:29 +0000] [14551] [INFO] Worker exiting (pid: 14551)
[2023-11-08 01:53:29 +0000] [14552] [INFO] Worker exiting (pid: 14552)
[2023-11-08 01:53:29 +0000] [14550] [ERROR] Worker (pid:14551) exited with code 3
[2023-11-08 01:53:59 +0000] [14550] [ERROR] Shutting down: Master
[2023-11-08 01:53:59 +0000] [14550] [ERROR] Reason: Worker failed to boot.
[2023-11-08 07:10:10 +0000] [39957] [INFO] Starting gunicorn 21.2.0
[2023-11-08 07:10:10 +0000] [39957] [INFO] Listening at: http://127.0.0.1:6900 (39957)
[2023-11-08 07:10:10 +0000] [39957] [INFO] Using worker: sync
[2023-11-08 07:10:10 +0000] [39958] [INFO] Booting worker with pid: 39958
[2023-11-08 07:10:10 +0000] [39959] [INFO] Booting worker with pid: 39959
[2023-11-08 07:10:10 +0000] [39958] [ERROR] Exception in worker process
Traceback (most recent call last):
  File "/home/ubuntu/webcomic-backend/venv/lib/python3.10/site-packages/mysql/connector/connection_cext.py", line 302, in _open_connection
    self._cmysql.connect(**cnx_kwargs)
_mysql_connector.MySQLInterfaceError: Access denied for user 'root'@'localhost'

The above exception was the direct cause of the following exception:

Traceback (most recent call last):
  File "/home/ubuntu/webcomic-backend/venv/lib/python3.10/site-packages/sqlalchemy/engine/base.py", line 145, in __init__
    self._dbapi_connection = engine.raw_connection()
  File "/home/ubuntu/webcomic-backend/venv/lib/python3.10/site-packages/sqlalchemy/engine/base.py", line 3288, in raw_connection
    return self.pool.connect()
  File "/home/ubuntu/webcomic-backend/venv/lib/python3.10/site-packages/sqlalchemy/pool/base.py", line 452, in connect
    return _ConnectionFairy._checkout(self)
  File "/home/ubuntu/webcomic-backend/venv/lib/python3.10/site-packages/sqlalchemy/pool/base.py", line 1267, in _checkout
    fairy = _ConnectionRecord.checkout(pool)
  File "/home/ubuntu/webcomic-backend/venv/lib/python3.10/site-packages/sqlalchemy/pool/base.py", line 716, in checkout
    rec = pool._do_get()
  File "/home/ubuntu/webcomic-backend/venv/lib/python3.10/site-packages/sqlalchemy/pool/impl.py", line 169, in _do_get
    with util.safe_reraise():
  File "/home/ubuntu/webcomic-backend/venv/lib/python3.10/site-packages/sqlalchemy/util/langhelpers.py", line 147, in __exit__
    raise exc_value.with_traceback(exc_tb)
  File "/home/ubuntu/webcomic-backend/venv/lib/python3.10/site-packages/sqlalchemy/pool/impl.py", line 167, in _do_get
    return self._create_connection()
  File "/home/ubuntu/webcomic-backend/venv/lib/python3.10/site-packages/sqlalchemy/pool/base.py", line 393, in _create_connection
    return _ConnectionRecord(self)
  File "/home/ubuntu/webcomic-backend/venv/lib/python3.10/site-packages/sqlalchemy/pool/base.py", line 678, in __init__
    self.__connect()
  File "/home/ubuntu/webcomic-backend/venv/lib/python3.10/site-packages/sqlalchemy/pool/base.py", line 902, in __connect
    with util.safe_reraise():
  File "/home/ubuntu/webcomic-backend/venv/lib/python3.10/site-packages/sqlalchemy/util/langhelpers.py", line 147, in __exit__
    raise exc_value.with_traceback(exc_tb)
  File "/home/ubuntu/webcomic-backend/venv/lib/python3.10/site-packages/sqlalchemy/pool/base.py", line 898, in __connect
    self.dbapi_connection = connection = pool._invoke_creator(self)
  File "/home/ubuntu/webcomic-backend/venv/lib/python3.10/site-packages/sqlalchemy/engine/create.py", line 637, in connect
    return dialect.connect(*cargs, **cparams)
  File "/home/ubuntu/webcomic-backend/venv/lib/python3.10/site-packages/sqlalchemy/engine/default.py", line 615, in connect
    return self.loaded_dbapi.connect(*cargs, **cparams)
  File "/home/ubuntu/webcomic-backend/venv/lib/python3.10/site-packages/mysql/connector/pooling.py", line 293, in connect
    return CMySQLConnection(*args, **kwargs)
  File "/home/ubuntu/webcomic-backend/venv/lib/python3.10/site-packages/mysql/connector/connection_cext.py", line 128, in __init__
    self.connect(**kwargs)
  File "/home/ubuntu/webcomic-backend/venv/lib/python3.10/site-packages/mysql/connector/abstracts.py", line 1217, in connect
    self._open_connection()
  File "/home/ubuntu/webcomic-backend/venv/lib/python3.10/site-packages/mysql/connector/connection_cext.py", line 307, in _open_connection
    raise get_mysql_exception(
mysql.connector.errors.ProgrammingError: 1698 (28000): Access denied for user 'root'@'localhost'

The above exception was the direct cause of the following exception:

Traceback (most recent call last):
  File "/home/ubuntu/webcomic-backend/venv/lib/python3.10/site-packages/gunicorn/arbiter.py", line 609, in spawn_worker
    worker.init_process()
  File "/home/ubuntu/webcomic-backend/venv/lib/python3.10/site-packages/gunicorn/workers/base.py", line 134, in init_process
    self.load_wsgi()
  File "/home/ubuntu/webcomic-backend/venv/lib/python3.10/site-packages/gunicorn/workers/base.py", line 146, in load_wsgi
    self.wsgi = self.app.wsgi()
  File "/home/ubuntu/webcomic-backend/venv/lib/python3.10/site-packages/gunicorn/app/base.py", line 67, in wsgi
    self.callable = self.load()
  File "/home/ubuntu/webcomic-backend/venv/lib/python3.10/site-packages/gunicorn/app/wsgiapp.py", line 58, in load
    return self.load_wsgiapp()
  File "/home/ubuntu/webcomic-backend/venv/lib/python3.10/site-packages/gunicorn/app/wsgiapp.py", line 48, in load_wsgiapp
    return util.import_app(self.app_uri)
  File "/home/ubuntu/webcomic-backend/venv/lib/python3.10/site-packages/gunicorn/util.py", line 371, in import_app
    mod = importlib.import_module(module)
  File "/usr/lib/python3.10/importlib/__init__.py", line 126, in import_module
    return _bootstrap._gcd_import(name[level:], package, level)
  File "<frozen importlib._bootstrap>", line 1050, in _gcd_import
  File "<frozen importlib._bootstrap>", line 1027, in _find_and_load
  File "<frozen importlib._bootstrap>", line 1006, in _find_and_load_unlocked
  File "<frozen importlib._bootstrap>", line 688, in _load_unlocked
  File "<frozen importlib._bootstrap_external>", line 883, in exec_module
  File "<frozen importlib._bootstrap>", line 241, in _call_with_frames_removed
  File "/home/ubuntu/webcomic-backend/src/wsgi.py", line 10, in <module>
    chapter_cache: ChapterCache = ChapterCache(app, chapter_repository)
  File "/home/ubuntu/webcomic-backend/src/service/caches.py", line 28, in __init__
    self.load()
  File "/home/ubuntu/webcomic-backend/src/service/caches.py", line 32, in load
    chapters: list[ComicChapter] = self._repository.get_all_chapters()
  File "/home/ubuntu/webcomic-backend/src/repositorys/Repositories.py", line 41, in get_all_chapters
    comic_chapters: List[ComicChapter] = self.db.session.execute(query).fetchall()
  File "/home/ubuntu/webcomic-backend/venv/lib/python3.10/site-packages/sqlalchemy/orm/scoping.py", line 723, in execute
    return self._proxied.execute(
  File "/home/ubuntu/webcomic-backend/venv/lib/python3.10/site-packages/sqlalchemy/orm/session.py", line 2246, in execute
    return self._execute_internal(
  File "/home/ubuntu/webcomic-backend/venv/lib/python3.10/site-packages/sqlalchemy/orm/session.py", line 2131, in _execute_internal
    conn = self._connection_for_bind(bind)
  File "/home/ubuntu/webcomic-backend/venv/lib/python3.10/site-packages/sqlalchemy/orm/session.py", line 1998, in _connection_for_bind
    return trans._connection_for_bind(engine, execution_options)
  File "<string>", line 2, in _connection_for_bind
  File "/home/ubuntu/webcomic-backend/venv/lib/python3.10/site-packages/sqlalchemy/orm/state_changes.py", line 139, in _go
    ret_value = fn(self, *arg, **kw)
  File "/home/ubuntu/webcomic-backend/venv/lib/python3.10/site-packages/sqlalchemy/orm/session.py", line 1123, in _connection_for_bind
    conn = bind.connect()
  File "/home/ubuntu/webcomic-backend/venv/lib/python3.10/site-packages/sqlalchemy/engine/base.py", line 3264, in connect
    return self._connection_cls(self)
  File "/home/ubuntu/webcomic-backend/venv/lib/python3.10/site-packages/sqlalchemy/engine/base.py", line 147, in __init__
    Connection._handle_dbapi_exception_noconnection(
  File "/home/ubuntu/webcomic-backend/venv/lib/python3.10/site-packages/sqlalchemy/engine/base.py", line 2426, in _handle_dbapi_exception_noconnection
    raise sqlalchemy_exception.with_traceback(exc_info[2]) from e
  File "/home/ubuntu/webcomic-backend/venv/lib/python3.10/site-packages/sqlalchemy/engine/base.py", line 145, in __init__
    self._dbapi_connection = engine.raw_connection()
  File "/home/ubuntu/webcomic-backend/venv/lib/python3.10/site-packages/sqlalchemy/engine/base.py", line 3288, in raw_connection
    return self.pool.connect()
  File "/home/ubuntu/webcomic-backend/venv/lib/python3.10/site-packages/sqlalchemy/pool/base.py", line 452, in connect
    return _ConnectionFairy._checkout(self)
  File "/home/ubuntu/webcomic-backend/venv/lib/python3.10/site-packages/sqlalchemy/pool/base.py", line 1267, in _checkout
    fairy = _ConnectionRecord.checkout(pool)
  File "/home/ubuntu/webcomic-backend/venv/lib/python3.10/site-packages/sqlalchemy/pool/base.py", line 716, in checkout
    rec = pool._do_get()
  File "/home/ubuntu/webcomic-backend/venv/lib/python3.10/site-packages/sqlalchemy/pool/impl.py", line 169, in _do_get
    with util.safe_reraise():
  File "/home/ubuntu/webcomic-backend/venv/lib/python3.10/site-packages/sqlalchemy/util/langhelpers.py", line 147, in __exit__
    raise exc_value.with_traceback(exc_tb)
  File "/home/ubuntu/webcomic-backend/venv/lib/python3.10/site-packages/sqlalchemy/pool/impl.py", line 167, in _do_get
    return self._create_connection()
  File "/home/ubuntu/webcomic-backend/venv/lib/python3.10/site-packages/sqlalchemy/pool/base.py", line 393, in _create_connection
    return _ConnectionRecord(self)
  File "/home/ubuntu/webcomic-backend/venv/lib/python3.10/site-packages/sqlalchemy/pool/base.py", line 678, in __init__
    self.__connect()
  File "/home/ubuntu/webcomic-backend/venv/lib/python3.10/site-packages/sqlalchemy/pool/base.py", line 902, in __connect
    with util.safe_reraise():
  File "/home/ubuntu/webcomic-backend/venv/lib/python3.10/site-packages/sqlalchemy/util/langhelpers.py", line 147, in __exit__
    raise exc_value.with_traceback(exc_tb)
  File "/home/ubuntu/webcomic-backend/venv/lib/python3.10/site-packages/sqlalchemy/pool/base.py", line 898, in __connect
    self.dbapi_connection = connection = pool._invoke_creator(self)
  File "/home/ubuntu/webcomic-backend/venv/lib/python3.10/site-packages/sqlalchemy/engine/create.py", line 637, in connect
    return dialect.connect(*cargs, **cparams)
  File "/home/ubuntu/webcomic-backend/venv/lib/python3.10/site-packages/sqlalchemy/engine/default.py", line 615, in connect
    return self.loaded_dbapi.connect(*cargs, **cparams)
  File "/home/ubuntu/webcomic-backend/venv/lib/python3.10/site-packages/mysql/connector/pooling.py", line 293, in connect
    return CMySQLConnection(*args, **kwargs)
  File "/home/ubuntu/webcomic-backend/venv/lib/python3.10/site-packages/mysql/connector/connection_cext.py", line 128, in __init__
    self.connect(**kwargs)
  File "/home/ubuntu/webcomic-backend/venv/lib/python3.10/site-packages/mysql/connector/abstracts.py", line 1217, in connect
    self._open_connection()
  File "/home/ubuntu/webcomic-backend/venv/lib/python3.10/site-packages/mysql/connector/connection_cext.py", line 307, in _open_connection
    raise get_mysql_exception(
sqlalchemy.exc.ProgrammingError: (mysql.connector.errors.ProgrammingError) 1698 (28000): Access denied for user 'root'@'localhost'
(Background on this error at: https://sqlalche.me/e/20/f405)
[2023-11-08 07:10:10 +0000] [39958] [INFO] Worker exiting (pid: 39958)
[2023-11-08 07:10:11 +0000] [39959] [ERROR] Exception in worker process
Traceback (most recent call last):
  File "/home/ubuntu/webcomic-backend/venv/lib/python3.10/site-packages/mysql/connector/connection_cext.py", line 302, in _open_connection
    self._cmysql.connect(**cnx_kwargs)
_mysql_connector.MySQLInterfaceError: Access denied for user 'root'@'localhost'

The above exception was the direct cause of the following exception:

Traceback (most recent call last):
  File "/home/ubuntu/webcomic-backend/venv/lib/python3.10/site-packages/sqlalchemy/engine/base.py", line 145, in __init__
    self._dbapi_connection = engine.raw_connection()
  File "/home/ubuntu/webcomic-backend/venv/lib/python3.10/site-packages/sqlalchemy/engine/base.py", line 3288, in raw_connection
    return self.pool.connect()
  File "/home/ubuntu/webcomic-backend/venv/lib/python3.10/site-packages/sqlalchemy/pool/base.py", line 452, in connect
    return _ConnectionFairy._checkout(self)
  File "/home/ubuntu/webcomic-backend/venv/lib/python3.10/site-packages/sqlalchemy/pool/base.py", line 1267, in _checkout
    fairy = _ConnectionRecord.checkout(pool)
  File "/home/ubuntu/webcomic-backend/venv/lib/python3.10/site-packages/sqlalchemy/pool/base.py", line 716, in checkout
    rec = pool._do_get()
  File "/home/ubuntu/webcomic-backend/venv/lib/python3.10/site-packages/sqlalchemy/pool/impl.py", line 169, in _do_get
    with util.safe_reraise():
  File "/home/ubuntu/webcomic-backend/venv/lib/python3.10/site-packages/sqlalchemy/util/langhelpers.py", line 147, in __exit__
    raise exc_value.with_traceback(exc_tb)
  File "/home/ubuntu/webcomic-backend/venv/lib/python3.10/site-packages/sqlalchemy/pool/impl.py", line 167, in _do_get
    return self._create_connection()
  File "/home/ubuntu/webcomic-backend/venv/lib/python3.10/site-packages/sqlalchemy/pool/base.py", line 393, in _create_connection
    return _ConnectionRecord(self)
  File "/home/ubuntu/webcomic-backend/venv/lib/python3.10/site-packages/sqlalchemy/pool/base.py", line 678, in __init__
    self.__connect()
  File "/home/ubuntu/webcomic-backend/venv/lib/python3.10/site-packages/sqlalchemy/pool/base.py", line 902, in __connect
    with util.safe_reraise():
  File "/home/ubuntu/webcomic-backend/venv/lib/python3.10/site-packages/sqlalchemy/util/langhelpers.py", line 147, in __exit__
    raise exc_value.with_traceback(exc_tb)
  File "/home/ubuntu/webcomic-backend/venv/lib/python3.10/site-packages/sqlalchemy/pool/base.py", line 898, in __connect
    self.dbapi_connection = connection = pool._invoke_creator(self)
  File "/home/ubuntu/webcomic-backend/venv/lib/python3.10/site-packages/sqlalchemy/engine/create.py", line 637, in connect
    return dialect.connect(*cargs, **cparams)
  File "/home/ubuntu/webcomic-backend/venv/lib/python3.10/site-packages/sqlalchemy/engine/default.py", line 615, in connect
    return self.loaded_dbapi.connect(*cargs, **cparams)
  File "/home/ubuntu/webcomic-backend/venv/lib/python3.10/site-packages/mysql/connector/pooling.py", line 293, in connect
    return CMySQLConnection(*args, **kwargs)
  File "/home/ubuntu/webcomic-backend/venv/lib/python3.10/site-packages/mysql/connector/connection_cext.py", line 128, in __init__
    self.connect(**kwargs)
  File "/home/ubuntu/webcomic-backend/venv/lib/python3.10/site-packages/mysql/connector/abstracts.py", line 1217, in connect
    self._open_connection()
  File "/home/ubuntu/webcomic-backend/venv/lib/python3.10/site-packages/mysql/connector/connection_cext.py", line 307, in _open_connection
    raise get_mysql_exception(
mysql.connector.errors.ProgrammingError: 1698 (28000): Access denied for user 'root'@'localhost'

The above exception was the direct cause of the following exception:

Traceback (most recent call last):
  File "/home/ubuntu/webcomic-backend/venv/lib/python3.10/site-packages/gunicorn/arbiter.py", line 609, in spawn_worker
    worker.init_process()
  File "/home/ubuntu/webcomic-backend/venv/lib/python3.10/site-packages/gunicorn/workers/base.py", line 134, in init_process
    self.load_wsgi()
  File "/home/ubuntu/webcomic-backend/venv/lib/python3.10/site-packages/gunicorn/workers/base.py", line 146, in load_wsgi
    self.wsgi = self.app.wsgi()
  File "/home/ubuntu/webcomic-backend/venv/lib/python3.10/site-packages/gunicorn/app/base.py", line 67, in wsgi
    self.callable = self.load()
  File "/home/ubuntu/webcomic-backend/venv/lib/python3.10/site-packages/gunicorn/app/wsgiapp.py", line 58, in load
    return self.load_wsgiapp()
  File "/home/ubuntu/webcomic-backend/venv/lib/python3.10/site-packages/gunicorn/app/wsgiapp.py", line 48, in load_wsgiapp
    return util.import_app(self.app_uri)
  File "/home/ubuntu/webcomic-backend/venv/lib/python3.10/site-packages/gunicorn/util.py", line 371, in import_app
    mod = importlib.import_module(module)
  File "/usr/lib/python3.10/importlib/__init__.py", line 126, in import_module
    return _bootstrap._gcd_import(name[level:], package, level)
  File "<frozen importlib._bootstrap>", line 1050, in _gcd_import
  File "<frozen importlib._bootstrap>", line 1027, in _find_and_load
  File "<frozen importlib._bootstrap>", line 1006, in _find_and_load_unlocked
  File "<frozen importlib._bootstrap>", line 688, in _load_unlocked
  File "<frozen importlib._bootstrap_external>", line 883, in exec_module
  File "<frozen importlib._bootstrap>", line 241, in _call_with_frames_removed
  File "/home/ubuntu/webcomic-backend/src/wsgi.py", line 10, in <module>
    chapter_cache: ChapterCache = ChapterCache(app, chapter_repository)
  File "/home/ubuntu/webcomic-backend/src/service/caches.py", line 28, in __init__
    self.load()
  File "/home/ubuntu/webcomic-backend/src/service/caches.py", line 32, in load
    chapters: list[ComicChapter] = self._repository.get_all_chapters()
  File "/home/ubuntu/webcomic-backend/src/repositorys/Repositories.py", line 41, in get_all_chapters
    comic_chapters: List[ComicChapter] = self.db.session.execute(query).fetchall()
  File "/home/ubuntu/webcomic-backend/venv/lib/python3.10/site-packages/sqlalchemy/orm/scoping.py", line 723, in execute
    return self._proxied.execute(
  File "/home/ubuntu/webcomic-backend/venv/lib/python3.10/site-packages/sqlalchemy/orm/session.py", line 2246, in execute
    return self._execute_internal(
  File "/home/ubuntu/webcomic-backend/venv/lib/python3.10/site-packages/sqlalchemy/orm/session.py", line 2131, in _execute_internal
    conn = self._connection_for_bind(bind)
  File "/home/ubuntu/webcomic-backend/venv/lib/python3.10/site-packages/sqlalchemy/orm/session.py", line 1998, in _connection_for_bind
    return trans._connection_for_bind(engine, execution_options)
  File "<string>", line 2, in _connection_for_bind
  File "/home/ubuntu/webcomic-backend/venv/lib/python3.10/site-packages/sqlalchemy/orm/state_changes.py", line 139, in _go
    ret_value = fn(self, *arg, **kw)
  File "/home/ubuntu/webcomic-backend/venv/lib/python3.10/site-packages/sqlalchemy/orm/session.py", line 1123, in _connection_for_bind
    conn = bind.connect()
  File "/home/ubuntu/webcomic-backend/venv/lib/python3.10/site-packages/sqlalchemy/engine/base.py", line 3264, in connect
    return self._connection_cls(self)
  File "/home/ubuntu/webcomic-backend/venv/lib/python3.10/site-packages/sqlalchemy/engine/base.py", line 147, in __init__
    Connection._handle_dbapi_exception_noconnection(
  File "/home/ubuntu/webcomic-backend/venv/lib/python3.10/site-packages/sqlalchemy/engine/base.py", line 2426, in _handle_dbapi_exception_noconnection
    raise sqlalchemy_exception.with_traceback(exc_info[2]) from e
  File "/home/ubuntu/webcomic-backend/venv/lib/python3.10/site-packages/sqlalchemy/engine/base.py", line 145, in __init__
    self._dbapi_connection = engine.raw_connection()
  File "/home/ubuntu/webcomic-backend/venv/lib/python3.10/site-packages/sqlalchemy/engine/base.py", line 3288, in raw_connection
    return self.pool.connect()
  File "/home/ubuntu/webcomic-backend/venv/lib/python3.10/site-packages/sqlalchemy/pool/base.py", line 452, in connect
    return _ConnectionFairy._checkout(self)
  File "/home/ubuntu/webcomic-backend/venv/lib/python3.10/site-packages/sqlalchemy/pool/base.py", line 1267, in _checkout
    fairy = _ConnectionRecord.checkout(pool)
  File "/home/ubuntu/webcomic-backend/venv/lib/python3.10/site-packages/sqlalchemy/pool/base.py", line 716, in checkout
    rec = pool._do_get()
  File "/home/ubuntu/webcomic-backend/venv/lib/python3.10/site-packages/sqlalchemy/pool/impl.py", line 169, in _do_get
    with util.safe_reraise():
  File "/home/ubuntu/webcomic-backend/venv/lib/python3.10/site-packages/sqlalchemy/util/langhelpers.py", line 147, in __exit__
    raise exc_value.with_traceback(exc_tb)
  File "/home/ubuntu/webcomic-backend/venv/lib/python3.10/site-packages/sqlalchemy/pool/impl.py", line 167, in _do_get
    return self._create_connection()
  File "/home/ubuntu/webcomic-backend/venv/lib/python3.10/site-packages/sqlalchemy/pool/base.py", line 393, in _create_connection
    return _ConnectionRecord(self)
  File "/home/ubuntu/webcomic-backend/venv/lib/python3.10/site-packages/sqlalchemy/pool/base.py", line 678, in __init__
    self.__connect()
  File "/home/ubuntu/webcomic-backend/venv/lib/python3.10/site-packages/sqlalchemy/pool/base.py", line 902, in __connect
    with util.safe_reraise():
  File "/home/ubuntu/webcomic-backend/venv/lib/python3.10/site-packages/sqlalchemy/util/langhelpers.py", line 147, in __exit__
    raise exc_value.with_traceback(exc_tb)
  File "/home/ubuntu/webcomic-backend/venv/lib/python3.10/site-packages/sqlalchemy/pool/base.py", line 898, in __connect
    self.dbapi_connection = connection = pool._invoke_creator(self)
  File "/home/ubuntu/webcomic-backend/venv/lib/python3.10/site-packages/sqlalchemy/engine/create.py", line 637, in connect
    return dialect.connect(*cargs, **cparams)
  File "/home/ubuntu/webcomic-backend/venv/lib/python3.10/site-packages/sqlalchemy/engine/default.py", line 615, in connect
    return self.loaded_dbapi.connect(*cargs, **cparams)
  File "/home/ubuntu/webcomic-backend/venv/lib/python3.10/site-packages/mysql/connector/pooling.py", line 293, in connect
    return CMySQLConnection(*args, **kwargs)
  File "/home/ubuntu/webcomic-backend/venv/lib/python3.10/site-packages/mysql/connector/connection_cext.py", line 128, in __init__
    self.connect(**kwargs)
  File "/home/ubuntu/webcomic-backend/venv/lib/python3.10/site-packages/mysql/connector/abstracts.py", line 1217, in connect
    self._open_connection()
  File "/home/ubuntu/webcomic-backend/venv/lib/python3.10/site-packages/mysql/connector/connection_cext.py", line 307, in _open_connection
    raise get_mysql_exception(
sqlalchemy.exc.ProgrammingError: (mysql.connector.errors.ProgrammingError) 1698 (28000): Access denied for user 'root'@'localhost'
(Background on this error at: https://sqlalche.me/e/20/f405)
[2023-11-08 07:10:11 +0000] [39959] [INFO] Worker exiting (pid: 39959)
[2023-11-08 07:10:11 +0000] [39957] [ERROR] Worker (pid:39958) exited with code 3
[2023-11-08 07:10:11 +0000] [39957] [ERROR] Worker (pid:39959) was sent SIGTERM!
[2023-11-08 07:10:11 +0000] [39957] [ERROR] Shutting down: Master
[2023-11-08 07:10:11 +0000] [39957] [ERROR] Reason: Worker failed to boot.
[2023-11-08 07:11:45 +0000] [40097] [INFO] Starting gunicorn 21.2.0
[2023-11-08 07:11:45 +0000] [40097] [INFO] Listening at: http://127.0.0.1:6900 (40097)
[2023-11-08 07:11:45 +0000] [40097] [INFO] Using worker: sync
[2023-11-08 07:11:45 +0000] [40098] [INFO] Booting worker with pid: 40098
[2023-11-08 07:11:45 +0000] [40099] [INFO] Booting worker with pid: 40099
